<?xml version="1.0" ?>
<!-- =================================================================================== -->
<!-- |    This document was autogenerated by xacro from navrover.xacro                 | -->
<!-- |    EDITING THIS FILE BY HAND IS NOT RECOMMENDED                                 | -->
<!-- =================================================================================== -->
<robot name="navrover">
  <!-- ==== ROBOT MAIN =============================================================================== -->
  <link name="base_footprint"/>
  <link name="imu_link"/>
  <!-- BASE LINK -->
  <link name="base_link">
    <visual>
      <origin rpy="0 0 0" xyz="0 0 0"/>
      <geometry>
        <mesh filename="file:///home/neptune/ws/example_ws/install/ugv_design/share/ugv_design/meshes/body.dae"/>
      </geometry>
    </visual>
    <collision>
      <origin rpy="0 0 0" xyz="0 0 0"/>
      <geometry>
        <mesh filename="file:///home/neptune/ws/example_ws/install/ugv_design/share/ugv_design/meshes/body.dae"/>
      </geometry>
    </collision>
    <inertial>
      <origin rpy="0 0 0" xyz="0 0 0"/>
      <mass value="1598"/>
      <inertia ixx="1997.86" ixy="-3e-05" ixz="-1e-06" iyy="442.769" iyz="62.5206" izz="2238.05"/>
    </inertial>
  </link>
  <link name="reverse_right_wheel_link">
    <visual>
      <origin rpy="0 0 0" xyz="0 0 0"/>
      <geometry>
        <mesh filename="file:///home/neptune/ws/example_ws/install/ugv_design/share/ugv_design/meshes/wheels/wheel_rear_right.dae"/>
      </geometry>
      <material name="">
        <color rgba="0.79216 0.81961 0.93333 1"/>
      </material>
    </visual>
    <collision>
      <origin rpy="0 0 0" xyz="0 0 0"/>
      <geometry>
        <mesh filename="file:///home/neptune/ws/example_ws/install/ugv_design/share/ugv_design/meshes/wheels/wheel_rear_right.dae"/>
      </geometry>
    </collision>
    <inertial>
      <origin rpy="0 0 0" xyz="0 0 0"/>
      <mass value="25"/>
      <inertia ixx="1.84514" ixy="0" ixz="0" iyy="1.04961" iyz="0" izz="1.04961"/>
    </inertial>
  </link>
  <link name="reverse_left_wheel_link">
    <visual>
      <origin rpy="0 0 0" xyz="0 0 0"/>
      <geometry>
        <mesh filename="file:///home/neptune/ws/example_ws/install/ugv_design/share/ugv_design/meshes/wheels/wheel_rear_left.dae"/>
      </geometry>
      <material name="">
        <color rgba="0.792156862745098 0.819607843137255 0.933333333333333 1"/>
      </material>
    </visual>
    <collision>
      <origin rpy="0 0 0" xyz="0 0 0"/>
      <geometry>
        <mesh filename="file:///home/neptune/ws/example_ws/install/ugv_design/share/ugv_design/meshes/wheels/wheel_rear_left.dae"/>
      </geometry>
    </collision>
    <inertial>
      <origin rpy="0 0 0" xyz="0 0 0"/>
      <mass value="25"/>
      <inertia ixx="1.84514" ixy="0" ixz="0" iyy="1.04961" iyz="0" izz="1.04961"/>
    </inertial>
  </link>
  <link name="front_left_wheel">
    <visual>
      <origin rpy="0 0 0" xyz="0 0 0"/>
      <geometry>
        <mesh filename="file:///home/neptune/ws/example_ws/install/ugv_design/share/ugv_design/meshes/wheels/wheel_front_left.dae"/>
      </geometry>
      <material name="">
        <color rgba="0.79216 0.81961 0.93333 1"/>
      </material>
    </visual>
    <collision>
      <origin rpy="0 0 0" xyz="0 0 0"/>
      <geometry>
        <mesh filename="file:///home/neptune/ws/example_ws/install/ugv_design/share/ugv_design/meshes/wheels/wheel_front_left.dae"/>
      </geometry>
    </collision>
    <inertial>
      <origin rpy="0 0 0" xyz="0 0 0"/>
      <mass value="25"/>
      <inertia ixx="1.84514" ixy="0" ixz="0" iyy="1.04961" iyz="0" izz="1.04961"/>
    </inertial>
  </link>
  <link name="front_right_wheel">
    <visual>
      <origin rpy="0 0 0" xyz="0 0 0"/>
      <geometry>
        <mesh filename="file:///home/neptune/ws/example_ws/install/ugv_design/share/ugv_design/meshes/wheels/wheel_front_right.dae"/>
      </geometry>
      <material name="">
        <color rgba="0.79216 0.81961 0.93333 1"/>
      </material>
    </visual>
    <collision>
      <origin rpy="0 0 0" xyz="0 0 0"/>
      <geometry>
        <mesh filename="file:///home/neptune/ws/example_ws/install/ugv_design/share/ugv_design/meshes/wheels/wheel_front_right.dae"/>
      </geometry>
    </collision>
    <inertial>
      <origin rpy="0 0 0" xyz="0 0 0"/>
      <mass value="25"/>
      <inertia ixx="1.84514" ixy="0" ixz="0" iyy="1.04961" iyz="0" izz="1.04961"/>
    </inertial>
  </link>
  <link name="front_left_steer">
    <visual>
      <origin rpy="0 0 0" xyz="0 0 0"/>
      <geometry>
        <mesh filename="file:///home/neptune/ws/example_ws/install/ugv_design/share/ugv_design/meshes/wheels/hub_front_left.dae"/>
      </geometry>
      <material name="">
        <color rgba="0.082353 0.56078 0 1"/>
      </material>
    </visual>
    <collision>
      <origin rpy="0 0 0" xyz="0 0 0"/>
      <geometry>
        <mesh filename="file:///home/neptune/ws/example_ws/install/ugv_design/share/ugv_design/meshes/wheels/hub_front_left.dae"/>
      </geometry>
    </collision>
    <inertial>
      <origin rpy="0 0 0" xyz="0 0 0"/>
      <mass value="1"/>
      <inertia ixx="1.84514" ixy="0" ixz="0" iyy="1.04961" iyz="0" izz="1.04961"/>
    </inertial>
  </link>
  <link name="front_right_steer">
    <visual>
      <origin rpy="0 0 0" xyz="0 0 0"/>
      <geometry>
        <mesh filename="file:///home/neptune/ws/example_ws/install/ugv_design/share/ugv_design/meshes/wheels/hub_front_right.dae"/>
      </geometry>
      <material name="">
        <color rgba="0.082353 0.56078 0 1"/>
      </material>
    </visual>
    <collision>
      <origin rpy="0 0 0" xyz="0 0 0"/>
      <geometry>
        <mesh filename="file:///home/neptune/ws/example_ws/install/ugv_design/share/ugv_design/meshes/wheels/hub_front_right.dae"/>
      </geometry>
    </collision>
    <inertial>
      <origin rpy="0 0 0" xyz="0 0 0"/>
      <mass value="1"/>
      <inertia ixx="1.84514" ixy="0" ixz="0" iyy="1.04961" iyz="0" izz="1.04961"/>
    </inertial>
  </link>
  <!--JOINTS ===================== -->
  <joint name="rear_right_wheel_joint" type="continuous">
    <origin rpy="0 0 0" xyz="-0.675 -0.685 0.324997"/>
    <parent link="base_link"/>
    <child link="reverse_right_wheel_link"/>
    <axis xyz="0 1 0"/>
  </joint>
  <joint name="rear_left_wheel_joint" type="continuous">
    <origin rpy="0 0 0" xyz="-0.675 0.685 0.324997"/>
    <parent link="base_link"/>
    <child link="reverse_left_wheel_link"/>
    <axis xyz="0 1 0"/>
  </joint>
  <joint name="front_left_wheel_joint" type="continuous">
    <origin rpy="0 0 0" xyz="0.0 0.174 0"/>
    <parent link="front_left_steer"/>
    <child link="front_left_wheel"/>
    <axis xyz="0 1 0"/>
  </joint>
  <joint name="front_right_wheel_joint" type="continuous">
    <origin rpy="0 0 0" xyz="0.0 -0.1693 0"/>
    <parent link="front_right_steer"/>
    <child link="front_right_wheel"/>
    <axis xyz="0 1 0"/>
  </joint>
  <joint name="front_left_steer_joint" type="revolute">
    <origin rpy="0 0 0" xyz="0.650 0.48290 0.324997"/>
    <parent link="base_link"/>
    <child link="front_left_steer"/>
    <axis xyz="0 0 1"/>
    <limit effort="10" lower="-0.6" upper="0.6" velocity="1"/>
  </joint>
  <joint name="front_right_steer_joint" type="revolute">
    <origin rpy="0 0 0" xyz="0.650 -0.5129 0.324997"/>
    <parent link="base_link"/>
    <child link="front_right_steer"/>
    <axis xyz="0 0 1"/>
    <limit effort="10" lower="-0.6" upper="0.6" velocity="1"/>
  </joint>
  <joint name="base_imu" type="fixed">
    <parent link="base_link"/>
    <child link="imu_link"/>
    <origin rpy="0 0 0" xyz="0 0 0"/>
  </joint>
  <joint name="base_footprint_joint" type="fixed">
    <parent link="base_footprint"/>
    <child link="base_link"/>
    <origin rpy="0 0 0" xyz="0.0 0.0 0.0215"/>
  </joint>
  <link name="steering_wheel"/>
  <joint name="steering_joint" type="revolute">
    <origin rpy="-0.002 0 0" xyz="0 0 0"/>
    <parent link="base_link"/>
    <child link="steering_wheel"/>
    <axis xyz="-0.964118 0.000768 0.265556"/>
    <dynamics damping="1.0" friction="0.01"/>
    <limit effort="1000.0" lower="-100" upper="100" velocity="100"/>
  </joint>
  <!-- ==== CAMERA =============================================================================== -->
  <link name="camera_front_link">
    <visual>
      <origin rpy="0 0 0" xyz="0 0 0"/>
      <geometry>
        <mesh filename="file:///home/neptune/ws/example_ws/install/ugv_design/share/ugv_design/meshes/accessories/camera_front.dae"/>
      </geometry>
      <material name="">
        <color rgba="1 1 1 1"/>
      </material>
    </visual>
    <collision>
      <origin rpy="0 0 0" xyz="0 0 0"/>
      <geometry>
        <mesh filename="file:///home/neptune/ws/example_ws/install/ugv_design/share/ugv_design/meshes/accessories/camera_front.dae"/>
      </geometry>
    </collision>
  </link>
  <link name="camera_back_link">
    <visual>
      <origin rpy="0 0 0" xyz="0 0 0"/>
      <geometry>
        <mesh filename="file:///home/neptune/ws/example_ws/install/ugv_design/share/ugv_design/meshes/accessories/camera_back.dae"/>
      </geometry>
      <material name="">
        <color rgba="1 1 1 1"/>
      </material>
    </visual>
    <collision>
      <origin rpy="0 0 0" xyz="0 0 0"/>
      <geometry>
        <mesh filename="file:///home/neptune/ws/example_ws/install/ugv_design/share/ugv_design/meshes/accessories/camera_back.dae"/>
      </geometry>
    </collision>
  </link>
  <joint name="camera_front_joint" type="fixed">
    <origin rpy="0 0 0" xyz="0 0 0"/>
    <parent link="base_link"/>
    <child link="camera_front_link"/>
    <axis xyz="0 0 0"/>
  </joint>
  <joint name="camera_back_joint" type="fixed">
    <origin rpy="0 0 0" xyz="0 0 0"/>
    <parent link="base_link"/>
    <child link="camera_back_link"/>
    <axis xyz="0 0 0"/>
  </joint>
  <!-- ==== LIDAR =============================================================================== -->
  <link name="laser_front_link">
    <visual>
      <origin rpy="0 0 -1.57" xyz="0 1 -0.95"/>
      <geometry>
        <mesh filename="file:///home/neptune/ws/example_ws/install/ugv_design/share/ugv_design/meshes/accessories/lidar_front.dae"/>
      </geometry>
      <material name="">
        <color rgba="1 1 1 1"/>
      </material>
    </visual>
    <collision>
      <origin rpy="0 0 -1.57" xyz="0 0 0"/>
      <geometry>
        <mesh filename="file:///home/neptune/ws/example_ws/install/ugv_design/share/ugv_design/meshes/accessories/lidar_front.dae"/>
      </geometry>
    </collision>
  </link>
  <link name="laser_back_link">
    <visual>
      <origin rpy="0 0 0" xyz="0 0 0"/>
      <geometry>
        <mesh filename="file:///home/neptune/ws/example_ws/install/ugv_design/share/ugv_design/meshes/accessories/lidar_back.dae"/>
      </geometry>
      <material name="">
        <color rgba="1 1 1 1"/>
      </material>
    </visual>
    <collision>
      <origin rpy="0 0 0" xyz="0 0 0"/>
      <geometry>
        <mesh filename="file:///home/neptune/ws/example_ws/install/ugv_design/share/ugv_design/meshes/accessories/lidar_back.dae"/>
      </geometry>
    </collision>
  </link>
  <joint name="laser_front_joint" type="fixed">
    <origin rpy="0 0 1.57" xyz="1 0 0.95"/>
    <parent link="base_link"/>
    <child link="laser_front_link"/>
  </joint>
  <joint name="laser_back_joint" type="fixed">
    <origin rpy="0 0 0" xyz="0 0 0"/>
    <parent link="base_link"/>
    <child link="laser_back_link"/>
  </joint>
  <gazebo reference="laser_front_link">
    <sensor name="lidar" type="ray">
      <pose>0 0 0 0 0 0</pose>
      <always_on>true</always_on>
      <visualize>true</visualize>
      <update_rate>10</update_rate>
      <ray>
        <scan>
          <horizontal>
            <samples>360</samples>
            <resolution>1.000000</resolution>
            <min_angle>0</min_angle>
            <max_angle>-3.14</max_angle>
          </horizontal>
        </scan>
        <range>
          <min>0.3</min>
          <max>15.0</max>
          <resolution>0.015</resolution>
        </range>
        <noise>
          <type>gaussian</type>
          <mean>0.0</mean>
          <stddev>0.01</stddev>
        </noise>
      </ray>
      <plugin filename="libgazebo_ros_ray_sensor.so" name="scan">
        <ros>
          <remapping>~/out:=scan</remapping>
        </ros>
        <output_type>sensor_msgs/LaserScan</output_type>
        <frame_name>laser_front_link</frame_name>
      </plugin>
    </sensor>
  </gazebo>
  <!-- ==== ULTRASOUND =============================================================================== -->
  <link name="ultra_sound_01_link">
    <inertial>
      <mass value="1e-5"/>
      <origin rpy="0 0 0" xyz="0 0 0"/>
      <inertia ixx="1e-6" ixy="0" ixz="0" iyy="1e-6" iyz="0" izz="1e-6"/>
    </inertial>
    <visual>
      <origin rpy="0 0 0" xyz="0 0 0"/>
      <geometry>
        <mesh filename="file:///home/neptune/ws/example_ws/install/ugv_design/share/ugv_design/meshes/ultrasound/UltraSound_01.stl"/>
      </geometry>
      <material name="">
        <color rgba="0 0 0 1"/>
      </material>
    </visual>
    <collision>
      <origin rpy="0 0 0" xyz="0 0 0"/>
      <geometry>
        <mesh filename="file:///home/neptune/ws/example_ws/install/ugv_design/share/ugv_design/meshes/ultrasound/UltraSound_01.stl"/>
      </geometry>
    </collision>
  </link>
  <link name="ultra_sound_02_link">
    <inertial>
      <mass value="1e-5"/>
      <origin rpy="0 0 0" xyz="0 0 0"/>
      <inertia ixx="1e-6" ixy="0" ixz="0" iyy="1e-6" iyz="0" izz="1e-6"/>
    </inertial>
    <visual>
      <origin rpy="0 0 0" xyz="0 0 0"/>
      <geometry>
        <mesh filename="file:///home/neptune/ws/example_ws/install/ugv_design/share/ugv_design/meshes/ultrasound/UltraSound_02.stl"/>
      </geometry>
      <material name="">
        <color rgba="0 0 0 1"/>
      </material>
    </visual>
    <collision>
      <origin rpy="0 0 0" xyz="0 0 0"/>
      <geometry>
        <mesh filename="file:///home/neptune/ws/example_ws/install/ugv_design/share/ugv_design/meshes/ultrasound/UltraSound_02.stl"/>
      </geometry>
    </collision>
  </link>
  <link name="ultra_sound_03_link">
    <inertial>
      <mass value="1e-5"/>
      <origin rpy="0 0 0" xyz="0 0 0"/>
      <inertia ixx="1e-6" ixy="0" ixz="0" iyy="1e-6" iyz="0" izz="1e-6"/>
    </inertial>
    <visual>
      <origin rpy="0 0 0" xyz="0 0 0"/>
      <geometry>
        <mesh filename="file:///home/neptune/ws/example_ws/install/ugv_design/share/ugv_design/meshes/ultrasound/UltraSound_03.stl"/>
      </geometry>
      <material name="">
        <color rgba="0 0 0 1"/>
      </material>
    </visual>
    <collision>
      <origin rpy="0 0 0" xyz="0 0 0"/>
      <geometry>
        <mesh filename="file:///home/neptune/ws/example_ws/install/ugv_design/share/ugv_design/meshes/ultrasound/UltraSound_03.stl"/>
      </geometry>
    </collision>
  </link>
  <link name="ultra_sound_04_link">
    <inertial>
      <mass value="1e-5"/>
      <origin rpy="0 0 0" xyz="0 0 0"/>
      <inertia ixx="1e-6" ixy="0" ixz="0" iyy="1e-6" iyz="0" izz="1e-6"/>
    </inertial>
    <visual>
      <origin rpy="0 0 0" xyz="0 0 0"/>
      <geometry>
        <mesh filename="file:///home/neptune/ws/example_ws/install/ugv_design/share/ugv_design/meshes/ultrasound/UltraSound_04.stl"/>
      </geometry>
      <material name="">
        <color rgba="0 0 0 1"/>
      </material>
    </visual>
    <collision>
      <origin rpy="0 0 0" xyz="0 0 0"/>
      <geometry>
        <mesh filename="file:///home/neptune/ws/example_ws/install/ugv_design/share/ugv_design/meshes/ultrasound/UltraSound_04.stl"/>
      </geometry>
    </collision>
  </link>
  <link name="ultra_sound_05_link">
    <inertial>
      <mass value="1e-5"/>
      <origin rpy="0 0 0" xyz="0 0 0"/>
      <inertia ixx="1e-6" ixy="0" ixz="0" iyy="1e-6" iyz="0" izz="1e-6"/>
    </inertial>
    <visual>
      <origin rpy="0 0 0" xyz="0 0 0"/>
      <geometry>
        <mesh filename="file:///home/neptune/ws/example_ws/install/ugv_design/share/ugv_design/meshes/ultrasound/UltraSound_05.stl"/>
      </geometry>
      <material name="">
        <color rgba="0 0 0 1"/>
      </material>
    </visual>
    <collision>
      <origin rpy="0 0 0" xyz="0 0 0"/>
      <geometry>
        <mesh filename="file:///home/neptune/ws/example_ws/install/ugv_design/share/ugv_design/meshes/ultrasound/UltraSound_05.stl"/>
      </geometry>
    </collision>
  </link>
  <link name="ultra_sound_06_link">
    <inertial>
      <mass value="1e-5"/>
      <origin rpy="0 0 0" xyz="0 0 0"/>
      <inertia ixx="1e-6" ixy="0" ixz="0" iyy="1e-6" iyz="0" izz="1e-6"/>
    </inertial>
    <visual>
      <origin rpy="0 0 0" xyz="0 0 0"/>
      <geometry>
        <mesh filename="file:///home/neptune/ws/example_ws/install/ugv_design/share/ugv_design/meshes/ultrasound/UltraSound_06.stl"/>
      </geometry>
      <material name="">
        <color rgba="0 0 0 1"/>
      </material>
    </visual>
    <collision>
      <origin rpy="0 0 0" xyz="0 0 0"/>
      <geometry>
        <mesh filename="file:///home/neptune/ws/example_ws/install/ugv_design/share/ugv_design/meshes/ultrasound/UltraSound_06.stl"/>
      </geometry>
    </collision>
  </link>
  <link name="ultra_sound_07_link">
    <inertial>
      <mass value="1e-5"/>
      <origin rpy="0 0 0" xyz="0 0 0"/>
      <inertia ixx="1e-6" ixy="0" ixz="0" iyy="1e-6" iyz="0" izz="1e-6"/>
    </inertial>
    <visual>
      <origin rpy="0 0 0" xyz="0 0 0"/>
      <geometry>
        <mesh filename="file:///home/neptune/ws/example_ws/install/ugv_design/share/ugv_design/meshes/ultrasound/UltraSound_07.stl"/>
      </geometry>
      <material name="">
        <color rgba="0 0 0 1"/>
      </material>
    </visual>
    <collision>
      <origin rpy="0 0 0" xyz="0 0 0"/>
      <geometry>
        <mesh filename="file:///home/neptune/ws/example_ws/install/ugv_design/share/ugv_design/meshes/ultrasound/UltraSound_07.stl"/>
      </geometry>
    </collision>
  </link>
  <link name="ultra_sound_08_link">
    <inertial>
      <mass value="1e-5"/>
      <origin rpy="0 0 0" xyz="0 0 0"/>
      <inertia ixx="1e-6" ixy="0" ixz="0" iyy="1e-6" iyz="0" izz="1e-6"/>
    </inertial>
    <visual>
      <origin rpy="0 0 0" xyz="0 0 0"/>
      <geometry>
        <mesh filename="file:///home/neptune/ws/example_ws/install/ugv_design/share/ugv_design/meshes/ultrasound/UltraSound_08.stl"/>
      </geometry>
      <material name="">
        <color rgba="0 0 0 1"/>
      </material>
    </visual>
    <collision>
      <origin rpy="0 0 0" xyz="0 0 0"/>
      <geometry>
        <mesh filename="file:///home/neptune/ws/example_ws/install/ugv_design/share/ugv_design/meshes/ultrasound/UltraSound_08.stl"/>
      </geometry>
    </collision>
  </link>
  <link name="ultra_sound_09_link">
    <inertial>
      <mass value="1e-5"/>
      <origin rpy="0 0 0" xyz="0 0 0"/>
      <inertia ixx="1e-6" ixy="0" ixz="0" iyy="1e-6" iyz="0" izz="1e-6"/>
    </inertial>
    <visual>
      <origin rpy="0 0 0" xyz="0 0 0"/>
      <geometry>
        <mesh filename="file:///home/neptune/ws/example_ws/install/ugv_design/share/ugv_design/meshes/ultrasound/UltraSound_09.stl"/>
      </geometry>
      <material name="">
        <color rgba="0 0 0 1"/>
      </material>
    </visual>
    <collision>
      <origin rpy="0 0 0" xyz="0 0 0"/>
      <geometry>
        <mesh filename="file:///home/neptune/ws/example_ws/install/ugv_design/share/ugv_design/meshes/ultrasound/UltraSound_09.stl"/>
      </geometry>
    </collision>
  </link>
  <link name="ultra_sound_10_link">
    <inertial>
      <mass value="1e-5"/>
      <origin rpy="0 0 0" xyz="0 0 0"/>
      <inertia ixx="1e-6" ixy="0" ixz="0" iyy="1e-6" iyz="0" izz="1e-6"/>
    </inertial>
    <visual>
      <origin rpy="0 0 0" xyz="0 0 0"/>
      <geometry>
        <mesh filename="file:///home/neptune/ws/example_ws/install/ugv_design/share/ugv_design/meshes/ultrasound/UltraSound_10.stl"/>
      </geometry>
      <material name="">
        <color rgba="0 0 0 1"/>
      </material>
    </visual>
    <collision>
      <origin rpy="0 0 0" xyz="0 0 0"/>
      <geometry>
        <mesh filename="file:///home/neptune/ws/example_ws/install/ugv_design/share/ugv_design/meshes/ultrasound/UltraSound_10.stl"/>
      </geometry>
    </collision>
  </link>
  <link name="ultra_sound_11_link">
    <inertial>
      <mass value="1e-5"/>
      <origin rpy="0 0 0" xyz="0 0 0"/>
      <inertia ixx="1e-6" ixy="0" ixz="0" iyy="1e-6" iyz="0" izz="1e-6"/>
    </inertial>
    <visual>
      <origin rpy="0 0 0" xyz="0 0 0"/>
      <geometry>
        <mesh filename="file:///home/neptune/ws/example_ws/install/ugv_design/share/ugv_design/meshes/ultrasound/UltraSound_11.stl"/>
      </geometry>
      <material name="">
        <color rgba="0 0 0 1"/>
      </material>
    </visual>
    <collision>
      <origin rpy="0 0 0" xyz="0 0 0"/>
      <geometry>
        <mesh filename="file:///home/neptune/ws/example_ws/install/ugv_design/share/ugv_design/meshes/ultrasound/UltraSound_11.stl"/>
      </geometry>
    </collision>
  </link>
  <link name="ultra_sound_12_link">
    <inertial>
      <mass value="1e-5"/>
      <origin rpy="0 0 0" xyz="0 0 0"/>
      <inertia ixx="1e-6" ixy="0" ixz="0" iyy="1e-6" iyz="0" izz="1e-6"/>
    </inertial>
    <visual>
      <origin rpy="0 0 0" xyz="0 0 0"/>
      <geometry>
        <mesh filename="file:///home/neptune/ws/example_ws/install/ugv_design/share/ugv_design/meshes/ultrasound/UltraSound_12.stl"/>
      </geometry>
      <material name="">
        <color rgba="0 0 0 1"/>
      </material>
    </visual>
    <collision>
      <origin rpy="0 0 0" xyz="0 0 0"/>
      <geometry>
        <mesh filename="file:///home/neptune/ws/example_ws/install/ugv_design/share/ugv_design/meshes/ultrasound/UltraSound_12.stl"/>
      </geometry>
    </collision>
  </link>
  <link name="ultra_sound_13_link">
    <inertial>
      <mass value="1e-5"/>
      <origin rpy="0 0 0" xyz="0 0 0"/>
      <inertia ixx="1e-6" ixy="0" ixz="0" iyy="1e-6" iyz="0" izz="1e-6"/>
    </inertial>
    <visual>
      <origin rpy="0 0 0" xyz="0 0 0"/>
      <geometry>
        <mesh filename="file:///home/neptune/ws/example_ws/install/ugv_design/share/ugv_design/meshes/ultrasound/UltraSound_13.stl"/>
      </geometry>
      <material name="">
        <color rgba="0 0 0 1"/>
      </material>
    </visual>
    <collision>
      <origin rpy="0 0 0" xyz="0 0 0"/>
      <geometry>
        <mesh filename="file:///home/neptune/ws/example_ws/install/ugv_design/share/ugv_design/meshes/ultrasound/UltraSound_13.stl"/>
      </geometry>
    </collision>
  </link>
  <link name="ultra_sound_14_link">
    <inertial>
      <mass value="1e-5"/>
      <origin rpy="0 0 0" xyz="0 0 0"/>
      <inertia ixx="1e-6" ixy="0" ixz="0" iyy="1e-6" iyz="0" izz="1e-6"/>
    </inertial>
    <visual>
      <origin rpy="0 0 0" xyz="0 0 0"/>
      <geometry>
        <mesh filename="file:///home/neptune/ws/example_ws/install/ugv_design/share/ugv_design/meshes/ultrasound/UltraSound_14.stl"/>
      </geometry>
      <material name="">
        <color rgba="0 0 0 1"/>
      </material>
    </visual>
    <collision>
      <origin rpy="0 0 0" xyz="0 0 0"/>
      <geometry>
        <mesh filename="file:///home/neptune/ws/example_ws/install/ugv_design/share/ugv_design/meshes/ultrasound/UltraSound_14.stl"/>
      </geometry>
    </collision>
  </link>
  <link name="ultra_sound_15_link">
    <inertial>
      <mass value="1e-5"/>
      <origin rpy="0 0 0" xyz="0 0 0"/>
      <inertia ixx="1e-6" ixy="0" ixz="0" iyy="1e-6" iyz="0" izz="1e-6"/>
    </inertial>
    <visual>
      <origin rpy="0 0 0" xyz="0 0 0"/>
      <geometry>
        <mesh filename="file:///home/neptune/ws/example_ws/install/ugv_design/share/ugv_design/meshes/ultrasound/UltraSound_15.stl"/>
      </geometry>
      <material name="">
        <color rgba="0 0 0 1"/>
      </material>
    </visual>
    <collision>
      <origin rpy="0 0 0" xyz="0 0 0"/>
      <geometry>
        <mesh filename="file:///home/neptune/ws/example_ws/install/ugv_design/share/ugv_design/meshes/ultrasound/UltraSound_15.stl"/>
      </geometry>
    </collision>
  </link>
  <link name="ultra_sound_16_link">
    <inertial>
      <mass value="1e-5"/>
      <origin rpy="0 0 0" xyz="0 0 0"/>
      <inertia ixx="1e-6" ixy="0" ixz="0" iyy="1e-6" iyz="0" izz="1e-6"/>
    </inertial>
    <visual>
      <origin rpy="0 0 0" xyz="0 0 0"/>
      <geometry>
        <mesh filename="file:///home/neptune/ws/example_ws/install/ugv_design/share/ugv_design/meshes/ultrasound/UltraSound_16.stl"/>
      </geometry>
      <material name="">
        <color rgba="0 0 0 1"/>
      </material>
    </visual>
    <collision>
      <origin rpy="0 0 0" xyz="0 0 0"/>
      <geometry>
        <mesh filename="file:///home/neptune/ws/example_ws/install/ugv_design/share/ugv_design/meshes/ultrasound/UltraSound_16.stl"/>
      </geometry>
    </collision>
  </link>
  <joint name="ultra_sound_01_joint" type="fixed">
    <origin rpy="0 0 0" xyz="0 0 0"/>
    <parent link="base_link"/>
    <child link="ultra_sound_01_link"/>
    <axis xyz="1 0 0"/>
  </joint>
  <joint name="ultra_sound_02_joint" type="fixed">
    <origin rpy="0 0 0" xyz="0 0 0"/>
    <parent link="base_link"/>
    <child link="ultra_sound_02_link"/>
    <axis xyz="1 0 0"/>
  </joint>
  <joint name="ultra_sound_03_joint" type="fixed">
    <origin rpy="0 0 0" xyz="0 0 0"/>
    <parent link="base_link"/>
    <child link="ultra_sound_03_link"/>
    <axis xyz="1 0 0"/>
  </joint>
  <joint name="ultra_sound_04_joint" type="fixed">
    <origin rpy="0 0 0" xyz="0 0 0"/>
    <parent link="base_link"/>
    <child link="ultra_sound_04_link"/>
    <axis xyz="1 0 0"/>
  </joint>
  <joint name="ultra_sound_05_joint" type="fixed">
    <origin rpy="0 0 0" xyz="0 0 0"/>
    <parent link="base_link"/>
    <child link="ultra_sound_05_link"/>
    <axis xyz="1 0 0"/>
  </joint>
  <joint name="ultra_sound_06_joint" type="fixed">
    <origin rpy="0 0 0" xyz="0 0 0"/>
    <parent link="base_link"/>
    <child link="ultra_sound_06_link"/>
    <axis xyz="1 0 0"/>
  </joint>
  <joint name="ultra_sound_07_joint" type="fixed">
    <origin rpy="0 0 0" xyz="0 0 0"/>
    <parent link="base_link"/>
    <child link="ultra_sound_07_link"/>
    <axis xyz="1 0 0"/>
  </joint>
  <joint name="ultra_sound_08_joint" type="fixed">
    <origin rpy="0 0 0" xyz="0 0 0"/>
    <parent link="base_link"/>
    <child link="ultra_sound_08_link"/>
    <axis xyz="1 0 0"/>
  </joint>
  <joint name="ultra_sound_09_joint" type="fixed">
    <origin rpy="0 0 0" xyz="0 0 0"/>
    <parent link="base_link"/>
    <child link="ultra_sound_09_link"/>
    <axis xyz="1 0 0"/>
  </joint>
  <joint name="ultra_sound_10_joint" type="fixed">
    <origin rpy="0 0 0" xyz="0 0 0"/>
    <parent link="base_link"/>
    <child link="ultra_sound_10_link"/>
    <axis xyz="1 0 0"/>
  </joint>
  <joint name="ultra_sound_11_joint" type="fixed">
    <origin rpy="0 0 0" xyz="0 0 0"/>
    <parent link="base_link"/>
    <child link="ultra_sound_11_link"/>
    <axis xyz="1 0 0"/>
  </joint>
  <joint name="ultra_sound_12_joint" type="fixed">
    <origin rpy="0 0 0" xyz="0 0 0"/>
    <parent link="base_link"/>
    <child link="ultra_sound_12_link"/>
    <axis xyz="1 0 0"/>
  </joint>
  <joint name="ultra_sound_13_joint" type="fixed">
    <origin rpy="0 0 0" xyz="0 0 0"/>
    <parent link="base_link"/>
    <child link="ultra_sound_13_link"/>
    <axis xyz="1 0 0"/>
  </joint>
  <joint name="ultra_sound_14_joint" type="fixed">
    <origin rpy="0 0 0" xyz="0 0 0"/>
    <parent link="base_link"/>
    <child link="ultra_sound_14_link"/>
    <axis xyz="1 0 0"/>
  </joint>
  <joint name="ultra_sound_15_joint" type="fixed">
    <origin rpy="0 0 0" xyz="0 0 0"/>
    <parent link="base_link"/>
    <child link="ultra_sound_15_link"/>
    <axis xyz="1 0 0"/>
  </joint>
  <joint name="ultra_sound_16_joint" type="fixed">
    <origin rpy="0 0 0" xyz="0 0 0"/>
    <parent link="base_link"/>
    <child link="ultra_sound_16_link"/>
    <axis xyz="1 0 0"/>
  </joint>
  <!-- ==== GAZEBO =============================================================================== -->
  <gazebo reference="reverse_right_wheel_link">
    <material>Gazebo/DarkGrey</material>
    <mu1>1.7</mu1>
    <mu2>1.7</mu2>
    <selfCollide>true</selfCollide>
  </gazebo>
  <gazebo reference="reverse_left_wheel_link">
    <material>Gazebo/DarkGrey</material>
    <mu1>1.7</mu1>
    <mu2>1.7</mu2>
    <selfCollide>true</selfCollide>
  </gazebo>
  <gazebo reference="front_right_wheel">
    <material>Gazebo/DarkGrey</material>
    <mu1>1.7</mu1>
    <mu2>1.7</mu2>
    <selfCollide>true</selfCollide>
  </gazebo>
  <gazebo reference="front_left_wheel">
    <material>Gazebo/DarkGrey</material>
    <mu1>1.7</mu1>
    <mu2>1.7</mu2>
    <selfCollide>true</selfCollide>
  </gazebo>
  <gazebo reference="r_steer_1">
    <material>Gazebo/DarkGrey</material>
    <mu1>0.2</mu1>
    <mu2>0.2</mu2>
    <selfCollide>true</selfCollide>
  </gazebo>
  <gazebo reference="front_right_steer">
    <material>Gazebo/DarkGrey</material>
    <mu1>0.2</mu1>
    <mu2>0.2</mu2>
    <selfCollide>true</selfCollide>
  </gazebo>
  <gazebo>
    <plugin filename="libgazebo_ros_ackermann_drive.so" name="gazebo_ros_ackermann_drive">
      <!-- <ros><namespace>demo</namespace><remapping>cmd_vel:=cmd_demo</remapping><remapping>odom:=odom_demo</remapping><remapping>distance:=distance_demo</remapping></ros> -->
      <update_rate>100.0</update_rate>
      <!-- wheels -->
      <front_left_joint>front_left_wheel_joint</front_left_joint>
      <front_right_joint>front_right_wheel_joint</front_right_joint>
      <rear_left_joint>rear_left_wheel_joint</rear_left_joint>
      <rear_right_joint>rear_right_wheel_joint</rear_right_joint>
      <left_steering_joint>front_left_steer_joint</left_steering_joint>
      <right_steering_joint>front_right_steer_joint</right_steering_joint>
      <!-- <steering_wheel_joint>steering_joint</steering_wheel_joint> -->
      <!-- Max absolute steer angle for tyre in radians-->
      <!-- Any cmd_vel angular z greater than this would be capped -->
      <max_steer>0.6458</max_steer>
      <!-- Max absolute steering angle of steering wheel -->
      <max_steering_angle>7.85</max_steering_angle>
      <!-- Max absolute linear speed in m/s -->
      <max_speed>20</max_speed>
      <!-- PID tuning -->
      <left_steering_pid_gain>1500 0 1</left_steering_pid_gain>
      <left_steering_i_range>0 0</left_steering_i_range>
      <right_steering_pid_gain>1500 0 1</right_steering_pid_gain>
      <right_steering_i_range>0 0</right_steering_i_range>
      <linear_velocity_pid_gain>1000 0 1</linear_velocity_pid_gain>
      <linear_velocity_i_range>0 0</linear_velocity_i_range>
      <!-- output -->
      <publish_odom>true</publish_odom>
      <publish_odom_tf>true</publish_odom_tf>
      <publish_wheel_tf>true</publish_wheel_tf>
      <publish_distance>true</publish_distance>
      <odometry_frame>odom_demo</odometry_frame>
      <robot_base_frame>base_footprint</robot_base_frame>
    </plugin>
  </gazebo>
  <!-- 
  <gazebo reference="laser_front_link"><sensor name="lidar" type="ray"><pose>5 5 5 5 5 5</pose><always_on>true</always_on><visualize>true</visualize><update_rate>10</update_rate><ray><scan><horizontal><samples>360</samples><resolution>1.000000</resolution><min_angle>0</min_angle><max_angle>-3.14</max_angle></horizontal></scan><range><min>0.3</min><max>15.0</max><resolution>0.015</resolution></range><noise><type>gaussian</type><mean>0.0</mean><stddev>0.01</stddev></noise></ray><plugin name="scan" filename="libgazebo_ros_ray_sensor.so"><ros><remapping>~/out:=scan</remapping></ros><output_type>sensor_msgs/LaserScan</output_type><frame_name>laser_front_link</frame_name></plugin></sensor></gazebo> -->
</robot>
