<?xml version="1.0"?>
<robot name="navrover"
	xmlns:xacro="http://www.ros.org/wiki/xacro">

<!-- ==== ROBOT MAIN =============================================================================== -->
 
 	<xacro:property name="wheel_mass" value="0.060236" />
	
	<xacro:macro name="default_inertial" params="mass">
		<inertial>
			<origin xyz="0 0 0" rpy="0 0 0"/>
			<mass value="${mass}" />
			<inertia ixx="1997.86" ixy="-3e-05" ixz="-1e-06"
                   iyy="442.769" iyz="62.5206"
                   izz="2238.05" />
		</inertial>
	</xacro:macro>
	<xacro:macro name="wheel_inertial" params="mass">
		<inertial>
			<origin xyz="0 0 0" rpy="0 0 0"/>
			<mass value="${mass}" />
			<inertia ixx="1.84514" ixy="0" ixz="0"
                   iyy="1.04961" iyz="0"
                   izz="1.04961" />
		</inertial>
	</xacro:macro>
	<xacro:macro name="steer_inertial" params="mass">
		<inertial>
			<origin xyz="0 0 0" rpy="0 0 0"/>
			<mass value="${mass}" />
			<inertia ixx="1.84514" ixy="0" ixz="0"
                   iyy="1.04961" iyz="0"
                   izz="1.04961" />
		</inertial>
	</xacro:macro>
	<link name="base_footprint"/>
	<!-- <link name="imu_link"/> -->
	<!-- BASE LINK -->
	<link name="base_link">
		<visual>
			<origin xyz="10 -20 0" rpy="0 0 1.57" />
			<geometry>
				<mesh filename="package://mini_ugv/meshes/edited_file/chassis.stl" scale="1 1 1"/>
			</geometry>
			<material name="">
				<color rgba="0.62 0.62 0.62 1" />
			</material>
		</visual>
		<collision>
			<origin xyz="0 0 0" rpy="0 0 0" />
			<geometry>
				<mesh filename="package://mini_ugv/meshes/edited_file/chassis.stl" scale="1 1 1"/>
			</geometry>
		</collision>
		<xacro:default_inertial mass="1598"/>
	</link>
	<link name="reverse_right_wheel_link">
		<visual>
			<origin xyz="0 0 0" rpy="0 0 0" />
			<geometry>
				<mesh filename="package://mini_ugv/meshes/edited_file/backleft_tire.stl" scale="1 1 1"/>
			</geometry>
			<material name="">
				<color rgba="0.169 0.169 0.169 1" scale="1 1 1"/>
			</material>
		</visual>
		<collision>
			<origin xyz="0 0 0" rpy="0 0 0" />
			<geometry>
				<mesh filename="package://mini_ugv/meshes/edited_file/backleft_tire.stl" scale="1 1 1"/>
			</geometry>
		</collision>
		<xacro:wheel_inertial mass="25"/>
	</link>
	<link name="reverse_left_wheel_link">
		<visual>
			<origin xyz="0 0 0" rpy="0 0 0" />
			<geometry>
				<mesh filename="package://mini_ugv/meshes/edited_file/backright_tire.stl" scale="1 1 1"/>
			</geometry>
			<material name="">
				<color rgba="0.169 0.169 0.169 1" scale="1 1 1"/>
			</material>
		</visual>
		<collision>
			<origin xyz="0 0 0" rpy="0 0 0" />
			<geometry>
				<mesh filename="package://mini_ugv/meshes/edited_file/backright_tire.stl" scale="1 1 1"/>
			</geometry>
		</collision>
		<xacro:wheel_inertial mass="25"/>
	</link>
	 <link name="front_left_wheel">
		<visual>
			<origin xyz="0 0 0" rpy="0 0 0" />
			<geometry>
				<mesh filename="package://mini_ugv/meshes/edited_file/frontleft_tire.stl" scale="1 1 1"/>
			</geometry>
			<material name="">
				<color rgba="0.169 0.169 0.169 1" scale="1 1 1"/>
			</material>
		</visual>
		<collision>
			<origin xyz="0 0 0" rpy="0 0 0" />
			<geometry>
				<mesh filename="package://mini_ugv/meshes/edited_file/frontleft_tire.stl" scale="1 1 1"/>
			</geometry>
		</collision>
		<xacro:wheel_inertial mass="25"/>
	</link>
	<link name="front_right_wheel">
		<visual>
			<origin xyz="0 0 0" rpy="0 0 0" />
			<geometry>
				<mesh filename="package://mini_ugv/meshes/edited_file/frontright_tire.stl" scale="1 1 1"/>
			</geometry>
			<material name="">
				<color rgba="0.169 0.169 0.169 1" scale="1 1 1"/>
			</material>
		</visual>
		<collision>
			<origin xyz="0 0 0" rpy="0 0 0" />
			<geometry>
				<mesh filename="package://mini_ugv/meshes/edited_file/frontright_tire.stl" scale="1 1 1"/>
			</geometry>
		</collision>
		<xacro:wheel_inertial mass="25"/>
	</link>
	<link name="front_left_steer">
		<visual>
			<origin xyz="0 0 0" rpy="0 0 0" />
			<geometry>
				<mesh filename="package://mini_ugv/meshes/edited_file/left_ackermann.stl" scale="1 1 1"/>
			</geometry>
			<material name="">
				<color rgba="0.62 0.62 0.62 1" />
			</material>
		</visual>
		<collision>
			<origin xyz="0 0 0" rpy="0 0 0" />
			<geometry>
				<mesh filename="package://mini_ugv/meshes/edited_file/left_ackermann.stl" scale="1 1 1"/>
			</geometry>
		</collision>
		<xacro:steer_inertial mass="1"/>
	</link>
	<link name="front_right_steer">
		<visual>
			<origin xyz="0 0 0" rpy="0 0 0" />
			<geometry>
				<mesh filename="package://mini_ugv/meshes/edited_file/right_ackermann.stl" scale="1 1 1"/>
			</geometry>
			<material name="">
				<color rgba="0.62 0.62 0.62 1" />
			</material>
		</visual>
		<collision>
			<origin xyz="0 0 0" rpy="0 0 0" />
			<geometry>
				<mesh filename="package://mini_ugv/meshes/edited_file/right_ackermann.stl" scale="1 1 1"/>
			</geometry>
		</collision>
		<xacro:steer_inertial mass="1"/>
	</link>

	<link name="laser_frame">
		<visual>
			<origin xyz="0 0 0" rpy="0 0 0" />
			<geometry>
				<mesh filename="package://mini_ugv/meshes/edited_file/right_ackermann.stl" scale="1 1 1"/>
			</geometry>
			<material name="">
				<color rgba="0.62 0.62 0.62 1" />
			</material>
		</visual>
		<collision>
			<origin xyz="0 0 0" rpy="0 0 0" />
			<geometry>
				<mesh filename="package://mini_ugv/meshes/edited_file/right_ackermann.stl" scale="1 1 1"/>
			</geometry>
		</collision>
		<xacro:steer_inertial mass="1"/>
	</link>
	<!--JOINTS ===================== -->
	<joint name="rear_left_wheel_joint" type="continuous">
		<origin xyz="-2.3848 -1.9643 0.2994" rpy="0 0 1.57" />
		<parent link="base_link" />
		<child link="reverse_left_wheel_link" />
		<axis xyz="1 0 0" />
	</joint>
	<joint name="rear_right_wheel_joint" type="continuous">
		<origin xyz="-2.3230 2.2809 0.3341" rpy="0 0 1.57" />
		<parent
	  link="base_link" />
		<child
	  link="reverse_right_wheel_link" />
		<axis xyz="1 0 0" />
	</joint>
	<joint name="front_left_wheel_joint" type="continuous">
		<origin xyz="-0.5 -0.11 0" rpy="0 0 0" />
		<parent link="front_left_steer" />
		<child
	  link="front_left_wheel" />
		<axis
	  xyz="1 0 0" />
	</joint>
	<joint name="front_right_wheel_joint" type="continuous">
		<origin xyz="0.5 -0.11 0" rpy="0 0 0" />
		<parent link="front_right_steer" />
		<child link="front_right_wheel" />
		<axis xyz="1 0 0" />
	</joint>
	<joint name="front_left_steer_joint" type="revolute">
		<origin xyz="1.4109 -1.4031 0.3452" rpy="0 0 1.57" />
		<parent link="base_link" />
		<child link="front_left_steer" />
		<axis xyz="0 0 1" />
		<limit lower="-0.6" upper="0.6" effort="10" velocity="1" />
	</joint>
	<joint name="front_right_steer_joint" type="revolute">
		<origin xyz="1.3357 1.7039 0.3452"  rpy="0 0 1.57" />
		<parent link="base_link" />
		<child link="front_right_steer" />
		<axis xyz="0 0 1" />
		<limit lower="-0.6" upper="0.6" effort="10" velocity="1" />
	</joint>
	<!--<joint name="base_imu" type="fixed">
		<parent link="base_link"/>
		<child link="imu_link"/>
		<origin xyz="0 0 0" rpy="0 0 0"/>
	</joint> -->
	<joint name="base_footprint_joint" type="fixed">
		<parent link="base_footprint"/>
		<child link="base_link"/>
		<origin xyz="0 0 0.11" rpy="0 0 0"/>
	</joint>
		<joint name="laser_joint" type="fixed">
		<parent link="base_link"/>
		<child link="laser_frame"/>
		<origin xyz="0 0 1.7" rpy="0 0 0"/>
	</joint>
	<!-- <link name="steering_wheel" />
	<joint name="steering_joint" type="revolute">
		<origin rpy="-0.002 0 0" xyz="0 0 0" />
		<parent link="base_link" />
		<child link="steering_wheel" />
		<axis xyz="-0.964118 0.000768 0.265556" />
		<dynamics damping="1.0" friction="0.01" />
		<limit effort="1000.0" lower="-100" upper="100" velocity="100" />
	</joint>  -->

	<!-- <xacro:include filename="$(find ugv_design)/urdf/rover_camera.xacro" />  -->
	 <!-- <xacro:include filename="$(find mini_ugv)/urdf/rover_lidar.xacro" />  -->
	<!-- <xacro:include filename="$(find ugv_design)/urdf/rover_ultrasound.xacro" /> -->
	 <!-- <xacro:include filename="$(find ugv_design)/urdf/rover.gazebo.xacro" /> -->
</robot>
