<?xml version="1.0"?>
<robot name="mini_ugv"
	xmlns:xacro="http://www.ros.org/wiki/xacro">
	<!-- ==== ROBOT MAIN =============================================================================== -->
	<xacro:property name="wheel_mass" value="0.060236" />
	<xacro:macro name="default_inertial" params="mass">
		<inertial>
			<origin xyz="0 0 0" rpy="0 0 0"/>
			<mass value="${mass}" />
			<inertia ixx="1997.86" ixy="-3e-05" ixz="-1e-06"
                   iyy="442.769" iyz="62.5206"
                   izz="2238.05" />
		</inertial>
	</xacro:macro>
	<xacro:macro name="wheel_inertial" params="mass">
		<inertial>
			<origin xyz="0 0 0" rpy="0 0 0"/>
			<mass value="${mass}" />
			<inertia ixx="1.84514" ixy="0" ixz="0"
                   iyy="1.04961" iyz="0"
                   izz="1.04961" />
		</inertial>
	</xacro:macro>
	<xacro:macro name="steer_inertial" params="mass">
		<inertial>
			<origin xyz="0 0 0" rpy="0 0 0"/>
			<mass value="${mass}" />
			<inertia ixx="1.84514" ixy="0" ixz="0"
                   iyy="1.04961" iyz="0"
                   izz="1.04961" />
		</inertial>
	</xacro:macro>
	<link name="base_footprint"/>
	<link name="imu_link"/>
	<!-- BASE LINK -->
	<link name="base_link">
		<visual>
			<origin xyz="0 0 0" rpy="0 0 0" />
			<geometry>
				<mesh filename="file://$(find mini_ugv)/meshes/body.dae" />
			</geometry>
		</visual>
		<collision>
			<origin xyz="0 0 0" rpy="0 0 0" />
			<geometry>
				<mesh filename="file://$(find mini_ugv)/meshes/body.dae" />
			</geometry>
		</collision>
		<xacro:default_inertial mass="1598"/>
	</link>
	<link name="reverse_right_wheel_link">
		<visual>
			<origin xyz="0 0 0" rpy="0 0 0" />
			<geometry>
				<mesh filename="file://$(find mini_ugv)/meshes/wheels/wheel_rear_right.dae" />
			</geometry>
			<material name="">
				<color rgba="0.79216 0.81961 0.93333 1" />
			</material>
		</visual>
		<collision>
			<origin xyz="0 0 0" rpy="0 0 0" />
			<geometry>
				<mesh filename="file://$(find mini_ugv)/meshes/wheels/wheel_rear_right.dae" />
			</geometry>
		</collision>
		<xacro:wheel_inertial mass="25"/>
	</link>
	<link name="reverse_left_wheel_link">
		<visual>
			<origin xyz="0 0 0" rpy="0 0 0" />
			<geometry>
				<mesh filename="file://$(find mini_ugv)/meshes/wheels/wheel_rear_left.dae" />
			</geometry>
			<material name="">
				<color rgba="0.792156862745098 0.819607843137255 0.933333333333333 1" />
			</material>
		</visual>
		<collision>
			<origin xyz="0 0 0" rpy="0 0 0" />
			<geometry>
				<mesh filename="file://$(find mini_ugv)/meshes/wheels/wheel_rear_left.dae" />
			</geometry>
		</collision>
		<xacro:wheel_inertial mass="25"/>
	</link>
	<link name="front_left_wheel">
		<visual>
			<origin xyz="0 0 0" rpy="0 0 0" />
			<geometry>
				<mesh filename="file://$(find mini_ugv)/meshes/wheels/wheel_front_left.dae" />
			</geometry>
			<material name="">
				<color rgba="0.79216 0.81961 0.93333 1" />
			</material>
		</visual>
		<collision>
			<origin xyz="0 0 0" rpy="0 0 0" />
			<geometry>
				<mesh filename="file://$(find mini_ugv)/meshes/wheels/wheel_front_left.dae" />
			</geometry>
		</collision>
		<xacro:wheel_inertial mass="25"/>
	</link>
	<link name="front_right_wheel">
		<visual>
			<origin xyz="0 0 0" rpy="0 0 0" />
			<geometry>
				<mesh filename="file://$(find mini_ugv)/meshes/wheels/wheel_front_right.dae" />
			</geometry>
			<material name="">
				<color rgba="0.79216 0.81961 0.93333 1" />
			</material>
		</visual>
		<collision>
			<origin xyz="0 0 0" rpy="0 0 0" />
			<geometry>
				<mesh
		  filename="file://$(find mini_ugv)/meshes/wheels/wheel_front_right.dae" />
			</geometry>
		</collision>
		<xacro:wheel_inertial mass="25"/>
	</link>
	<link name="front_left_steer">
		<visual>
			<origin xyz="0 0 0" rpy="0 0 0" />
			<geometry>
				<mesh filename="file://$(find mini_ugv)/meshes/wheels/hub_front_left.dae" />
			</geometry>
			<material name="">
				<color rgba="0.082353 0.56078 0 1" />
			</material>
		</visual>
		<collision>
			<origin xyz="0 0 0" rpy="0 0 0" />
			<geometry>
				<mesh filename="file://$(find mini_ugv)/meshes/wheels/hub_front_left.dae" />
			</geometry>
		</collision>
		<xacro:steer_inertial mass="1"/>
	</link>
	<link name="front_right_steer">
		<visual>
			<origin xyz="0 0 0" rpy="0 0 0" />
			<geometry>
				<mesh filename="file://$(find mini_ugv)/meshes/wheels/hub_front_right.dae" />
			</geometry>
			<material name="">
				<color rgba="0.082353 0.56078 0 1" />
			</material>
		</visual>
		<collision>
			<origin xyz="0 0 0" rpy="0 0 0" />
			<geometry>
				<mesh filename="file://$(find mini_ugv)/meshes/wheels/hub_front_right.dae" />
			</geometry>
		</collision>
		<xacro:steer_inertial mass="1"/>
	</link>
	<!--JOINTS ===================== -->
	<joint name="rear_right_wheel_joint" type="continuous">
		<origin xyz="-0.675 -0.685 0.324997" rpy="0 0 0" />
		<parent link="base_link" />
		<child link="reverse_right_wheel_link" />
		<axis xyz="0 1 0" />
	</joint>
	<joint name="rear_left_wheel_joint" type="continuous">
		<origin xyz="-0.675 0.685 0.324997" rpy="0 0 0" />
		<parent
	  link="base_link" />
		<child
	  link="reverse_left_wheel_link" />
		<axis xyz="0 1 0" />
	</joint>
	<joint name="front_left_wheel_joint" type="continuous">
		<origin xyz="0.0 0.174 0" rpy="0 0 0" />
		<parent link="front_left_steer" />
		<child
	  link="front_left_wheel" />
		<axis
	  xyz="0 1 0" />
	</joint>
	<joint name="front_right_wheel_joint" type="continuous">
		<origin xyz="0.0 -0.1693 0" rpy="0 0 0" />
		<parent link="front_right_steer" />
		<child link="front_right_wheel" />
		<axis xyz="0 1 0" />
	</joint>
	<joint name="front_left_steer_joint" type="revolute">
		<origin xyz="0.650 0.48290 0.324997" rpy="0 0 0" />
		<parent link="base_link" />
		<child link="front_left_steer" />
		<axis xyz="0 0 1" />
		<limit lower="-0.6" upper="0.6" effort="10" velocity="1" />
	</joint>
	<joint name="front_right_steer_joint" type="revolute">
		<origin xyz="0.650 -0.5129 0.324997"  rpy="0 0 0" />
		<parent link="base_link" />
		<child link="front_right_steer" />
		<axis xyz="0 0 1" />
		<limit lower="-0.6" upper="0.6" effort="10" velocity="1" />
	</joint>
	<joint name="base_imu" type="fixed">
		<parent link="base_link"/>
		<child link="imu_link"/>
		<origin xyz="0 0 0" rpy="0 0 0"/>
	</joint>
	<joint name="base_footprint_joint" type="fixed">
		<parent link="base_footprint"/>
		<child link="base_link"/>
		<origin xyz="0.0 0.0 0.0215" rpy="0 0 0"/>
	</joint>
	<link name="steering_wheel" />
	<joint name="steering_joint" type="revolute">
		<origin rpy="-0.002 0 0" xyz="0 0 0" />
		<parent link="base_link" />
		<child link="steering_wheel" />
		<axis xyz="-0.964118 0.000768 0.265556" />
		<dynamics damping="1.0" friction="0.01" />
		<limit effort="1000.0" lower="-100" upper="100" velocity="100" />
	</joint>
	<xacro:include filename="$(find mini_ugv)/urdf/rover_camera.xacro" />
	<!-- <xacro:include filename="$(find mini_ugv)/urdf/rover_lidar.xacro" /> -->
	<!-- <xacro:include filename="$(find mini_ugv)/urdf/rover_ultrasound.xacro" /> -->
	<!-- <xacro:include filename="$(find mini_ugv)/urdf/rover.gazebo.xacro" /> -->

	<!-- ==== LIDAR =============================================================================== -->
	<link name="laser_frame">
		<visual>
			<origin rpy="0 0 0" xyz="0 0 0"/>
			<geometry>
				<mesh filename="file://$(find mini_ugv)/meshes/accessories/lidar_front.dae"/>
			</geometry>
			<material name="">
				<color rgba="1 1 1 1"/>
			</material>
		</visual>
		<collision>
			<origin rpy="0 0 0" xyz="0 0 0"/>
			<geometry>
				<mesh filename="file://$(find mini_ugv)/meshes/accessories/lidar_front.dae"/>
			</geometry>
		</collision>
	</link>
	
	<joint name="laser_joint" type="fixed">
		<origin rpy="0 0 0" xyz="0 0 0.5"/>
		<parent link="base_link"/>
		<child link="laser_frame"/>
	</joint>

</robot>
