<?xml version="1.0" ?>
<!-- =================================================================================== -->
<!-- |    This document was autogenerated by xacro from navrover.xacro                 | -->
<!-- |    EDITING THIS FILE BY HAND IS NOT RECOMMENDED                                 | -->
<!-- =================================================================================== -->
<robot name="mini_ugv">
  <link name="base_footprint"/>
  <link name="imu_link"/>
  <!-- BASE LINK -->
  <link name="base_link">
    <visual>
      <origin rpy="0 0 0" xyz="0 0 0"/>
      <geometry>
        <mesh filename="file:///home/navcon/ws/mina_ws/install/mini_ugv/share/mini_ugv/meshes/body.dae"/>
      </geometry>
    </visual>
    <collision>
      <origin rpy="0 0 0" xyz="0 0 0"/>
      <geometry>
        <mesh filename="file:///home/navcon/ws/mina_ws/install/mini_ugv/share/mini_ugv/meshes/body.dae"/>
      </geometry>
    </collision>
    <inertial>
      <origin rpy="0 0 0" xyz="0 0 0"/>
      <mass value="1598"/>
      <inertia ixx="1997.86" ixy="-3e-05" ixz="-1e-06" iyy="442.769" iyz="62.5206" izz="2238.05"/>
    </inertial>
  </link>
  <link name="reverse_right_wheel_link">
    <visual>
      <origin rpy="0 0 0" xyz="0 0 0"/>
      <geometry>
        <mesh filename="file:///home/navcon/ws/mina_ws/install/mini_ugv/share/mini_ugv/meshes/wheels/wheel_rear_right.dae"/>
      </geometry>
      <material name="">
        <color rgba="0.79216 0.81961 0.93333 1"/>
      </material>
    </visual>
    <collision>
      <origin rpy="0 0 0" xyz="0 0 0"/>
      <geometry>
        <mesh filename="file:///home/navcon/ws/mina_ws/install/mini_ugv/share/mini_ugv/meshes/wheels/wheel_rear_right.dae"/>
      </geometry>
    </collision>
    <inertial>
      <origin rpy="0 0 0" xyz="0 0 0"/>
      <mass value="25"/>
      <inertia ixx="1.84514" ixy="0" ixz="0" iyy="1.04961" iyz="0" izz="1.04961"/>
    </inertial>
  </link>
  <link name="reverse_left_wheel_link">
    <visual>
      <origin rpy="0 0 0" xyz="0 0 0"/>
      <geometry>
        <mesh filename="file:///home/navcon/ws/mina_ws/install/mini_ugv/share/mini_ugv/meshes/wheels/wheel_rear_left.dae"/>
      </geometry>
      <material name="">
        <color rgba="0.792156862745098 0.819607843137255 0.933333333333333 1"/>
      </material>
    </visual>
    <collision>
      <origin rpy="0 0 0" xyz="0 0 0"/>
      <geometry>
        <mesh filename="file:///home/navcon/ws/mina_ws/install/mini_ugv/share/mini_ugv/meshes/wheels/wheel_rear_left.dae"/>
      </geometry>
    </collision>
    <inertial>
      <origin rpy="0 0 0" xyz="0 0 0"/>
      <mass value="25"/>
      <inertia ixx="1.84514" ixy="0" ixz="0" iyy="1.04961" iyz="0" izz="1.04961"/>
    </inertial>
  </link>
  <link name="front_left_wheel">
    <visual>
      <origin rpy="0 0 0" xyz="0 0 0"/>
      <geometry>
        <mesh filename="file:///home/navcon/ws/mina_ws/install/mini_ugv/share/mini_ugv/meshes/wheels/wheel_front_left.dae"/>
      </geometry>
      <material name="">
        <color rgba="0.79216 0.81961 0.93333 1"/>
      </material>
    </visual>
    <collision>
      <origin rpy="0 0 0" xyz="0 0 0"/>
      <geometry>
        <mesh filename="file:///home/navcon/ws/mina_ws/install/mini_ugv/share/mini_ugv/meshes/wheels/wheel_front_left.dae"/>
      </geometry>
    </collision>
    <inertial>
      <origin rpy="0 0 0" xyz="0 0 0"/>
      <mass value="25"/>
      <inertia ixx="1.84514" ixy="0" ixz="0" iyy="1.04961" iyz="0" izz="1.04961"/>
    </inertial>
  </link>
  <link name="front_right_wheel">
    <visual>
      <origin rpy="0 0 0" xyz="0 0 0"/>
      <geometry>
        <mesh filename="file:///home/navcon/ws/mina_ws/install/mini_ugv/share/mini_ugv/meshes/wheels/wheel_front_right.dae"/>
      </geometry>
      <material name="">
        <color rgba="0.79216 0.81961 0.93333 1"/>
      </material>
    </visual>
    <collision>
      <origin rpy="0 0 0" xyz="0 0 0"/>
      <geometry>
        <mesh filename="file:///home/navcon/ws/mina_ws/install/mini_ugv/share/mini_ugv/meshes/wheels/wheel_front_right.dae"/>
      </geometry>
    </collision>
    <inertial>
      <origin rpy="0 0 0" xyz="0 0 0"/>
      <mass value="25"/>
      <inertia ixx="1.84514" ixy="0" ixz="0" iyy="1.04961" iyz="0" izz="1.04961"/>
    </inertial>
  </link>
  <link name="front_left_steer">
    <visual>
      <origin rpy="0 0 0" xyz="0 0 0"/>
      <geometry>
        <mesh filename="file:///home/navcon/ws/mina_ws/install/mini_ugv/share/mini_ugv/meshes/wheels/hub_front_left.dae"/>
      </geometry>
      <material name="">
        <color rgba="0.082353 0.56078 0 1"/>
      </material>
    </visual>
    <collision>
      <origin rpy="0 0 0" xyz="0 0 0"/>
      <geometry>
        <mesh filename="file:///home/navcon/ws/mina_ws/install/mini_ugv/share/mini_ugv/meshes/wheels/hub_front_left.dae"/>
      </geometry>
    </collision>
    <inertial>
      <origin rpy="0 0 0" xyz="0 0 0"/>
      <mass value="1"/>
      <inertia ixx="1.84514" ixy="0" ixz="0" iyy="1.04961" iyz="0" izz="1.04961"/>
    </inertial>
  </link>
  <link name="front_right_steer">
    <visual>
      <origin rpy="0 0 0" xyz="0 0 0"/>
      <geometry>
        <mesh filename="file:///home/navcon/ws/mina_ws/install/mini_ugv/share/mini_ugv/meshes/wheels/hub_front_right.dae"/>
      </geometry>
      <material name="">
        <color rgba="0.082353 0.56078 0 1"/>
      </material>
    </visual>
    <collision>
      <origin rpy="0 0 0" xyz="0 0 0"/>
      <geometry>
        <mesh filename="file:///home/navcon/ws/mina_ws/install/mini_ugv/share/mini_ugv/meshes/wheels/hub_front_right.dae"/>
      </geometry>
    </collision>
    <inertial>
      <origin rpy="0 0 0" xyz="0 0 0"/>
      <mass value="1"/>
      <inertia ixx="1.84514" ixy="0" ixz="0" iyy="1.04961" iyz="0" izz="1.04961"/>
    </inertial>
  </link>
  <!--JOINTS ===================== -->
  <joint name="rear_right_wheel_joint" type="continuous">
    <origin rpy="0 0 0" xyz="-0.675 -0.685 0.324997"/>
    <parent link="base_link"/>
    <child link="reverse_right_wheel_link"/>
    <axis xyz="0 1 0"/>
  </joint>
  <joint name="rear_left_wheel_joint" type="continuous">
    <origin rpy="0 0 0" xyz="-0.675 0.685 0.324997"/>
    <parent link="base_link"/>
    <child link="reverse_left_wheel_link"/>
    <axis xyz="0 1 0"/>
  </joint>
  <joint name="front_left_wheel_joint" type="continuous">
    <origin rpy="0 0 0" xyz="0.0 0.174 0"/>
    <parent link="front_left_steer"/>
    <child link="front_left_wheel"/>
    <axis xyz="0 1 0"/>
  </joint>
  <joint name="front_right_wheel_joint" type="continuous">
    <origin rpy="0 0 0" xyz="0.0 -0.1693 0"/>
    <parent link="front_right_steer"/>
    <child link="front_right_wheel"/>
    <axis xyz="0 1 0"/>
  </joint>
  <joint name="front_left_steer_joint" type="revolute">
    <origin rpy="0 0 0" xyz="0.650 0.48290 0.324997"/>
    <parent link="base_link"/>
    <child link="front_left_steer"/>
    <axis xyz="0 0 1"/>
    <limit effort="10" lower="-0.6" upper="0.6" velocity="1"/>
  </joint>
  <joint name="front_right_steer_joint" type="revolute">
    <origin rpy="0 0 0" xyz="0.650 -0.5129 0.324997"/>
    <parent link="base_link"/>
    <child link="front_right_steer"/>
    <axis xyz="0 0 1"/>
    <limit effort="10" lower="-0.6" upper="0.6" velocity="1"/>
  </joint>
  <joint name="base_imu" type="fixed">
    <parent link="base_link"/>
    <child link="imu_link"/>
    <origin rpy="0 0 0" xyz="0 0 0"/>
  </joint>
  <joint name="base_footprint_joint" type="fixed">
    <parent link="base_footprint"/>
    <child link="base_link"/>
    <origin rpy="0 0 0" xyz="0.0 0.0 0.0215"/>
  </joint>
  <link name="steering_wheel"/>
  <joint name="steering_joint" type="revolute">
    <origin rpy="-0.002 0 0" xyz="0 0 0"/>
    <parent link="base_link"/>
    <child link="steering_wheel"/>
    <axis xyz="-0.964118 0.000768 0.265556"/>
    <dynamics damping="1.0" friction="0.01"/>
    <limit effort="1000.0" lower="-100" upper="100" velocity="100"/>
  </joint>
  <!-- ==== CAMERA =============================================================================== -->
  <link name="camera_link">
    <visual>
      <origin rpy="0 0 0" xyz="0 0 0"/>
      <geometry>
        <mesh filename="file:///home/navcon/ws/mina_ws/install/mini_ugv/share/mini_ugv/meshes/accessories/camera_front.dae"/>
      </geometry>
      <material name="">
        <color rgba="1 1 1 1"/>
      </material>
    </visual>
    <collision>
      <origin rpy="0 0 0" xyz="0 0 0"/>
      <geometry>
        <mesh filename="file:///home/navcon/ws/mina_ws/install/mini_ugv/share/mini_ugv/meshes/accessories/camera_front.dae"/>
      </geometry>
    </collision>
  </link>
  <joint name="camera_joint" type="fixed">
    <origin rpy="0 0 0" xyz="1.06182 -0.021586 0.883543"/>
    <parent link="base_link"/>
    <child link="camera_link"/>
    <axis xyz="0 0 0"/>
  </joint>
  <!-- <xacro:include filename="$(find mini_ugv)/urdf/rover_lidar.xacro" /> -->
  <!-- <xacro:include filename="$(find mini_ugv)/urdf/rover_ultrasound.xacro" /> -->
  <!-- <xacro:include filename="$(find mini_ugv)/urdf/rover.gazebo.xacro" /> -->
  <!-- ==== LIDAR =============================================================================== -->
  <link name="laser_frame">
    <visual>
      <origin rpy="0 0 0" xyz="0 0 0"/>
      <geometry>
        <mesh filename="file:///home/navcon/ws/mina_ws/install/mini_ugv/share/mini_ugv/meshes/accessories/lidar_front.dae"/>
      </geometry>
      <material name="">
        <color rgba="1 1 1 1"/>
      </material>
    </visual>
    <collision>
      <origin rpy="0 0 0" xyz="0 0 0"/>
      <geometry>
        <mesh filename="file:///home/navcon/ws/mina_ws/install/mini_ugv/share/mini_ugv/meshes/accessories/lidar_front.dae"/>
      </geometry>
    </collision>
  </link>
  <joint name="laser_joint" type="fixed">
    <origin rpy="0 0 0" xyz="0 0 0.5"/>
    <parent link="base_link"/>
    <child link="laser_frame"/>
  </joint>
</robot>
